Workbook

Sheet VULNERABILITY ASSESSMENT
A1: 👑 Asset | B1: 🌡️ Severity | C1: 🏆 CVSS | D1: 🏷️ Nessus ID | E1: 👋🏼 Name | F1: 🧨 CVE | G1: 🛡️ Solution | H1: 👾 Exploitability | I1: 💥 Impact | J1: 🎖️ Priority
A2: The hostname or IP address of affected device. | B2: How dangerous the vulnerability is. | C2: The numerical score showing severity (0-10). | D2: 6-digit unique ID associated with the Nessus plugin for detecting this vuln. | E2: The title or description of the vulnerability. | F2: The Common Vulnerabilities and Exposures identifier for reference. | G2: Recommended actions to fix the issue. | H2: The numerical score showing exploitability (0-10). | I2: The numerical score showing impact (0-10). | J2: Auto-calculated priority
A3: · The Host Information section. | B3: · Risk Factor section. | C3: · CVSS v3.0 Base Score section. | D3: · Plugin ID field in the vulnerability's title. | E3: · Plugin Name field in the vulnerability's title. | F3: · References section, under the CVE field. | G3: · Solution section. | H3: ANALYSIS: "Assess 👾 Exploitability" task | I3: ANALYSIS: "Assess 💥 Impact" task | J3: ANALYSIS: "Assessing your vulns' 🎖️ Priority ranking" task
A4: 10.20.30.10 (megaquagga.local) | B4: Critical | C4: 10 | D4: 58987 | E4: PHP Unsupported Version Detected | F4: N/A | G4: Upgrade to a version of PHP that is currently supported. | H4: 10 | I4: 10 | J4: =IFERROR(AVERAGE(C4, I4, H4), "") -> 10
A5: 10.20.30.10 (megaquagga.local) | B5: Critical | C5: 9.8 | D5: 200162 | E5: PHP 8.2x < 8.2.20 Multiple Vulnerabilities | F5: CVE-2024-4577, CVE-2024-5458, CVE-2024-5585 | G5: Upgrade to PHP version 8.2.20 or later. | H5: 9 | I5: 9.5 | J5: =IFERROR(AVERAGE(C5, I5, H5), "") -> 9.4333333
A6: 10.20.30.10 (megaquagga.local) | B6: Critical | C6: 9.8 | D6: 179906 | E6: PHP 8.2x < 8.2.9 Multiple Vulnerabilities | F6: CVE-2023-3823, CVE-2023-3824 | G6: Upgrade to PHP version 8.2.9 or later. | H6: 9 | I6: 9.5 | J6: =IFERROR(AVERAGE(C6, I6, H6), "") -> 9.4333333
A7: 10.20.30.10 (megaquagga.local) | B7: Critical | C7: 9.8 | D7: 211671 | E7: PHP 8.2x < 8.2.26 Multiple Vulnerabilities | F7: CVE-2024-8929, CVE-2024-8932, CVE-2024-11233, CVE-2024-11234, CVE-2024-11236 | G7: Upgrade to PHP version 8.2.26 or later. | H7: 9 | I7: 9.5 | J7: =IFERROR(AVERAGE(C7, I7, H7), "") -> 9.4333333
A8: 10.20.30.10 (megaquagga.local) | B8: High | C8: 8.8 | D8: 207822 | E8: PHP 8.2.x < 8.2.24 Multiple Vulnerabilities | F8: CVE-2024-8925, CVE-2024-8926, CVE-2024-8927, CVE-2024-9026 | G8: Upgrade to PHP version 8.2.24 or later. | H8: 8 | I8: 8 | J8: 8.8
A9: 10.20.30.10 (megaquagga.local) | B9: High | C9: 8.6 | D9: 232707 | E9: PHP 8.2.x < 8.2.28 Multiple Vulnerabilities | F9: CVE-2025-1217, CVE-2025-1219, CVE-2025-1734, CVE-2025-1736, CVE-2025-1861 | G9: Upgrade to PHP version 8.2.28 or later. | H9: 8 | I9: 8 | J9: 8.6
A10: 10.20.30.10 (megaquagga.local) | B10: High | C10: 7.5 | D10: 241291 | E10: PHP 8.2.x < 8.2.29 Multiple Vulnerabilities | F10: CVE-2025-1220, CVE-2025-1735, CVE-2025-6491 | G10: Upgrade to PHP version 8.2.29 or later. | H10: 7.5 | I10: 8 | J10: 7.5
A11: 10.20.30.10 (megaquagga.local) | B11: High | C11: 7.5 | D11: 279274 | E11: PHP 8.2.x < 8.2.30 Multiple Vulnerabilities | F11: CVE-2025-14177, CVE-2025-14178, CVE-2025-14180 | G11: Upgrade to PHP version 8.2.30 or later. | H11: 7.5 | I11: 8 | J11: 7.5
A12: 10.20.30.10 (megaquagga.local) | B12: High | C12: 7.5 | D12: 142591 | E12: PHP < 7.3.24 Multiple Vulnerabilities | F12: N/A | G12: Upgrade to PHP version 7.3.24 or later. | H12: 7.5 | I12: 8 | J12: 7.5
A13: 10.20.30.10 (megaquagga.local) | B13: Medium | C13: 6.5 | D13: 193191 | E13: PHP 8.2.x < 8.2.18 Multiple Vulnerabilities | F13: CVE-2022-31629, CVE-2024-1874, CVE-2024-2756, CVE-2024-3096 | G13: Upgrade to PHP version 8.2.18 or later. | H13: 6 | I13: 6.1 | J13: 6.5
A14: 10.20.30.10 (megaquagga.local) | B14: Medium | C14: 5.3 | D14: 152853 | E14: PHP < 7.3.28 Email Header Injection | F14: N/A | G14: Upgrade to PHP version 7.3.28 or later. | H14: 6 | I14: 6.1 | J14: 5.3
A15: 10.20.30.11 | B15: High | C15: 7.5 | D15: 42873 | E15: SSL Medium Strength Cipher Suites Supported (SWEET32) | F15: CVE-2016-2183 | G15: Reconfigure the affected application if possible to avoid use of medium strength ciphers. | H15: 7 | I15: 7.5 | J15: 7.5
A16: 10.20.30.11 | B16: Medium | C16: 6.5 | D16: 51192 | E16: SSL Certificate Cannot Be Trusted | F16: N/A | G16: Purchase or generate a proper SSL certificate for this service. | H16: 6 | I16: 6.1 | J16: 6.5
A17: 10.20.30.11 | B17: Medium | C17: 6.5 | D17: 57582 | E17: SSL Self-Signed Certificate | F17: N/A | G17: Purchase or generate a proper SSL certificate for this service. | H17: 6 | I17: 6.1 | J17: 6.5
A18: 10.20.30.11 | B18: Medium | C18: 5.3 | D18: 57608 | E18: SMB Signing not required | F18: N/A | G18: Enforce message signing in the host's configuration. On Windows, this is found in the policy setting 'Microsoft network server: Digitally sign communications (always)'. On Samba, the setting is called 'server signing'. See the 'see also' links for further details. | H18: 5 | I18: 5.1 | J18: 5.3
A19: 10.20.30.11 | B19: Low | C19: 2.1 | D19: 10114 | E19: ICMP Timestamp Request Remote Date Disclosure | F19: CVE-1999-0524 | G19: Filter out the ICMP timestamp requests (13), and the outgoing ICMP timestamp replies (14). | H19: 2.5 | I19: 3 | J19: 2.1
A20: 10.20.30.12 | B20: Critical | C20: 9.9 | D20: 270678 | E20: Ubuntu 14.04 LTS / 16.04 LTS / 18.04 LTS / 20.04 LTS / 24.04 LTS / 25.04 / 25.10 : Redis vulnerability (USN-7824-1) | F20: CVE-2025-49844 | G20: Update the affected packages. | H20: 9.8 | I20: 9.8 | J20: =IFERROR(AVERAGE(C20, I20, H20), "") -> 9.8333333
A21: 10.20.30.12 | B21: Critical | C21: 9.8 | D21: 297660 | E21: Ubuntu 22.04 LTS / 24.04 LTS / 25.10 : Inetutils vulnerability (USN-7992-1) | F21: CVE-2026-24061 | G21: Update the affected packages. | H21: 9.8 | I21: 9.8 | J21: =IFERROR(AVERAGE(C21, I21, H21), "") -> 9.8
A22: 10.20.30.12 | B22: Critical | C22: 9.8 | D22: 234681 | E22: Ubuntu 14.04 LTS / 16.04 LTS / 18.04 LTS / 20.04 LTS / 22.04 LTS / 24.04 LTS : Eclipse Mosquitto vulnerabilities (USN-7441-1) | F22: CVE-2024-3935, CVE-2024-10525 | G22: Update the affected packages. | H22: 9.8 | I22: 9.8 | J22: =IFERROR(AVERAGE(C22, I22, H22), "") -> 9.8
A23: 10.20.30.12 | B23: Critical | C23: 9.8 | D23: 288869 | E23: Ubuntu 14.04 LTS / 16.04 LTS / 18.04 LTS / 20.04 LTS / 22.04 LTS / 24.04 LTS / 25.04 / 25.10 : klibc vulnerabilities (USN-7959-1) | F23: CVE-2016-9843 | G23: Update the affected klibc-utils, libklibc and / or libklibc-dev packages. | H23: 9.8 | I23: 9.8 | J23: =IFERROR(AVERAGE(C23, I23, H23), "") -> 9.8
A24: 10.20.30.12 | B24: Critical | C24: 9.8 | D24: 261428 | E24: Ubuntu 18.04 LTS / 20.04 LTS / 22.04 LTS / 24.04 LTS / 25.04 : Ruby vulnerabilities (USN-7734-1) | F24: N/A | G24: Update the affected packages. | H24: 9.8 | I24: 9.8 | J24: =IFERROR(AVERAGE(C24, I24, H24), "") -> 9.8
A25: 10.20.30.12 | B25: Critical | C25: 9.8 | D25: 216780 | E25: Ubuntu 14.04 LTS / 16.04 LTS / 18.04 LTS / 20.04 LTS / 22.04 LTS / 24.04 LTS / 24.10 : libxml2 vulnerabilities (USN-7302-1) | F25: CVE-2022-49043, CVE-2024-34459, CVE-2024-56171, CVE-2025-24928, CVE-2025-27113 | G25: Update the affected packages. | H25: 9.8 | I25: 9.8 | J25: =IFERROR(AVERAGE(C25, I25, H25), "") -> 9.8
A26: 10.20.30.12 | B26: Critical | C26: 9.8 | D26: 205548 | E26: Ubuntu 20.04 LTS / 22.04 LTS / 24.04 LTS : BusyBox vulnerabilities (USN-6961-1) | F26: CVE-2022-48174, CVE-2023-42363, CVE-2023-42364, CVE-2023-42365 | G26: Update the affected packages. | H26: 9.8 | I26: 9.8 | J26: =IFERROR(AVERAGE(C26, I26, H26), "") -> 9.8
A27: 10.20.30.12 | B27: Critical | C27: 9.8 | D27: 209121 | E27: Ubuntu 14.04 LTS / 16.04 LTS / 18.04 LTS / 20.04 LTS / 22.04 LTS / 24.04 LTS : libarchive vulnerabilities (USN-7070-1) | F27: CVE-2022-36227, CVE-2024-48957, CVE-2024-48958 | G27: Update the affected packages. | H27: 9.8 | I27: 9.8 | J27: =IFERROR(AVERAGE(C27, I27, H27), "") -> 9.8
A28: 10.20.30.12 | B28: Critical | C28: 9.8 | D28: 211522 | E28: Ubuntu 16.04 LTS / 18.04 LTS / 20.04 LTS / 22.04 LTS / 24.04 LTS : GLib vulnerability (USN-7114-1) | F28: CVE-2024-52533 | G28: Update the affected packages. | H28: 9.8 | I28: 9.8 | J28: =IFERROR(AVERAGE(C28, I28, H28), "") -> 9.8
A29: 10.20.30.12 | B29: Critical | C29: 9.8 | D29: 234343 | E29: Ubuntu 22.04 LTS / 24.04 LTS / 24.10 : Perl vulnerability (USN-7434-1) | F29: CVE-2024-56406 | G29: Update the affected packages. | H29: 9.8 | I29: 9.8 | J29: =IFERROR(AVERAGE(C29, I29, H29), "") -> 9.8
A30: 10.20.30.12 | B30: Critical | C30: 9.8 | D30: 265698 | E30: Ubuntu 18.04 LTS / 20.04 LTS / 22.04 LTS / 24.04 LTS / 25.04 : OpenJPEG vulnerabilities (USN-7757-1) | F30: CVE-2025-50952, CVE-2025-54874 | G30: Update the affected packages. | H30: 9.8 | I30: 9.8 | J30: =IFERROR(AVERAGE(C30, I30, H30), "") -> 9.8
A31: 10.20.30.12 | B31: Critical | C31: 9.8 | D31: 241063 | E31: Ubuntu 22.04 LTS / 24.04 LTS / 24.10 / 25.04 : libarchive vulnerabilities (USN-7601-1) | F31: CVE-2025-5914, CVE-2025-5915, CVE-2025-5916, CVE-2025-5917 | G31: Update the affected packages. | H31: 9.8 | I31: 9.8 | J31: =IFERROR(AVERAGE(C31, I31, H31), "") -> 9.8
A32: 10.20.30.12 | B32: Critical | C32: 9.8 | D32: 233470 | E32: Ubuntu 20.04 LTS / 22.04 LTS / 24.04 LTS / 24.10 : Ghostscript vulnerabilities (USN-7378-1) | F32: CVE-2025-27830, CVE-2025-27831, CVE-2025-27832, CVE-2025-27833, CVE-2025-27834, CVE-2025-27835, CVE-2025-27836 | G32: Update the affected packages. | H32: 9.8 | I32: 9.8 | J32: =IFERROR(AVERAGE(C32, I32, H32), "") -> 9.8
A33: 10.20.30.12 | B33: Critical | C33: 9.8 | D33: 233831 | E33: Ubuntu 24.04 LTS / 24.10 : XZ Utils vulnerability (USN-7414-1) | F33: CVE-2025-31115 | G33: Update the affected packages. | H33: 9.8 | I33: 9.8 | J33: 9.8
A34: 10.20.30.12 | B34: Critical | C34: 9.8 | D34: 265092 | E34: Ubuntu 24.04 LTS / 25.04 : SQLite vulnerability (USN-7751-1) | F34: CVE-2025-7709 | G34: Update the affected packages. | H34: 9.5 | I34: 9.5 | J34: 9.8
A35: 10.20.30.12 | B35: Critical | C35: 9.8 | D35: 213189 | E35: Ubuntu 20.04 LTS / 22.04 LTS / 24.04 LTS / 24.10 : GStreamer vulnerability (USN-7174-1) | F35: CVE-2024-47606 | G35: Update the affected packages. | H35: 9.5 | I35: 9.5 | J35: =IFERROR(AVERAGE(C35, I35, H35), "") -> 9.6
A36: 10.20.30.12 | B36: Critical | C36: 9.8 | D36: 207059 | E36: Ubuntu 14.04 LTS / 16.04 LTS / 18.04 LTS / 20.04 LTS / 24.04 LTS : Expat vulnerabilities (USN-7000-1) | F36: CVE-2024-45490, CVE-2024-45491, CVE-2024-45492 | G36: Update the affected packages. | H36: 9.5 | I36: 9.5 | J36: =IFERROR(AVERAGE(C36, I36, H36), "") -> 9.6
A37: 10.20.30.12 | B37: Critical | C37: 9.8 | D37: 243033 | E37: Ubuntu 22.04 LTS / 24.04 LTS / 25.04 : SQLite vulnerability (USN-7676-1) | F37: CVE-2025-6965 | G37: Update the affected packages. | H37: 9.5 | I37: 9.5 | J37: =IFERROR(AVERAGE(C37, I37, H37), "") -> 9.6
A38: 10.20.30.12 | B38: Critical | C38: 9.8 | D38: 282466 | E38: Ubuntu 14.04 LTS / 16.04 LTS / 18.04 LTS / 20.04 LTS / 22.04 LTS / 24.04 LTS / 25.04 / 25.10 : Net-SNMP vulnerability (USN-7944-1) | F38: CVE-2025-68615 | G38: Update the affected packages. | H38: 9.5 | I38: 9.5 | J38: =IFERROR(AVERAGE(C38, I38, H38), "") -> 9.6
A39: 10.20.30.12 | B39: Critical | C39: 9.4 | D39: 240210 | E39: Ubuntu 24.04 LTS / 24.10 / 25.04 : Python vulnerabilities (USN-7583-1) | F39: CVE-2024-12718, CVE-2025-4138, CVE-2025-4330, CVE-2025-4435, CVE-2025-4517 | G39: Update the affected packages. | H39: 9.4 | I39: 9.5 | J39: 9.4
A40: 10.20.30.12 | B40: Critical | C40: 9.1 | D40: 204924 | E40: Ubuntu 20.04 LTS / 22.04 LTS / 24.04 LTS : OpenSSL vulnerabilities (USN-6937-1) | F40: CVE-2024-2511, CVE-2024-4603, CVE-2024-4741, CVE-2024-5535 | G40: Update the affected packages. | H40: 9.1 | I40: 9.5 | J40: 9.1
...

Sheet Vulns by Asset

Sheet Top Vulnerabilities
A1: 🏷️ Nessus ID | B1: 👋🏼 Name | C1: 🎖️ Priority | D1: 👑 Asset
A2: =IFERROR(__xludf.DUMMYFUNCTION("SORT( FILTER( {'VULNERABILITY ASSESSMENT'!D4:D1000, 'VULNERABILITY ASSESSMENT'!E4:E1000, 'VULNERABILITY ASSESSMENT'!J4:J1000, 'VULNERABILITY ASSESSMENT'!A4:A1000}, LEN('VULNERABILITY ASSESSMENT'!D4:D1000) > 0 ), 3, FALSE )"),"58987") -> 58987 | B2: =IFERROR(__xludf.DUMMYFUNCTION("""COMPUTED_VALUE"""),"PHP Unsupported Version Detected") -> PHP Unsupported Version Detected | C2: =IFERROR(__xludf.DUMMYFUNCTION("""COMPUTED_VALUE"""),10.0) -> 10 | D2: =IFERROR(__xludf.DUMMYFUNCTION("""COMPUTED_VALUE"""),"10.20.30.10 (megaquagga.local)") -> 10.20.30.10 (megaquagga.local)
A3: =IFERROR(__xludf.DUMMYFUNCTION("""COMPUTED_VALUE"""),"270678") -> 270678 | B3: =IFERROR(__xludf.DUMMYFUNCTION("""COMPUTED_VALUE"""),"Ubuntu 14.04 LTS / 16.04 LTS / 18.04 LTS / 20.04 LTS / 24.04 LTS / 25.04 / 25.10 : Redis vulnerability (USN-7824-1)") -> Ubuntu 14.04 LTS / 16.04 LTS / 18.04 LTS / 20.04 LTS / 24.04 LTS / 25.04 / 25.10 : Redis vulnerability (USN-7824-1) | C3: =IFERROR(__xludf.DUMMYFUNCTION("""COMPUTED_VALUE"""),9.833333333333334) -> 9.8333333 | D3: =IFERROR(__xludf.DUMMYFUNCTION("""COMPUTED_VALUE"""),"10.20.30.12") -> 10.20.30.12
A4: =IFERROR(__xludf.DUMMYFUNCTION("""COMPUTED_VALUE"""),"297660") -> 297660 | B4: =IFERROR(__xludf.DUMMYFUNCTION("""COMPUTED_VALUE"""),"Ubuntu 22.04 LTS / 24.04 LTS / 25.10 : Inetutils vulnerability (USN-7992-1)") -> Ubuntu 22.04 LTS / 24.04 LTS / 25.10 : Inetutils vulnerability (USN-7992-1) | C4: =IFERROR(__xludf.DUMMYFUNCTION("""COMPUTED_VALUE"""),9.8) -> 9.8 | D4: =IFERROR(__xludf.DUMMYFUNCTION("""COMPUTED_VALUE"""),"10.20.30.12") -> 10.20.30.12
A5: =IFERROR(__xludf.DUMMYFUNCTION("""COMPUTED_VALUE"""),"234681") -> 234681 | B5: =IFERROR(__xludf.DUMMYFUNCTION("""COMPUTED_VALUE"""),"Ubuntu 14.04 LTS / 16.04 LTS / 18.04 LTS / 20.04 LTS / 22.04 LTS / 24.04 LTS : Eclipse Mosquitto vulnerabilities (USN-7441-1)") -> Ubuntu 14.04 LTS / 16.04 LTS / 18.04 LTS / 20.04 LTS / 22.04 LTS / 24.04 LTS : Eclipse Mosquitto vulnerabilities (USN-7441-1) | C5: =IFERROR(__xludf.DUMMYFUNCTION("""COMPUTED_VALUE"""),9.8) -> 9.8 | D5: =IFERROR(__xludf.DUMMYFUNCTION("""COMPUTED_VALUE"""),"10.20.30.12") -> 10.20.30.12
A6: =IFERROR(__xludf.DUMMYFUNCTION("""COMPUTED_VALUE"""),"288869") -> 288869 | B6: =IFERROR(__xludf.DUMMYFUNCTION("""COMPUTED_VALUE"""),"Ubuntu 14.04 LTS / 16.04 LTS / 18.04 LTS / 20.04 LTS / 22.04 LTS / 24.04 LTS / 25.04 / 25.10 : klibc vulnerabilities (USN-7959-1)") -> Ubuntu 14.04 LTS / 16.04 LTS / 18.04 LTS / 20.04 LTS / 22.04 LTS / 24.04 LTS / 25.04 / 25.10 : klibc vulnerabilities (USN-7959-1) | C6: =IFERROR(__xludf.DUMMYFUNCTION("""COMPUTED_VALUE"""),9.8) -> 9.8 | D6: =IFERROR(__xludf.DUMMYFUNCTION("""COMPUTED_VALUE"""),"10.20.30.12") -> 10.20.30.12
A7: =IFERROR(__xludf.DUMMYFUNCTION("""COMPUTED_VALUE"""),"261428") -> 261428 | B7: =IFERROR(__xludf.DUMMYFUNCTION("""COMPUTED_VALUE"""),"Ubuntu 18.04 LTS / 20.04 LTS / 22.04 LTS / 24.04 LTS / 25.04 : Ruby vulnerabilities (USN-7734-1)") -> Ubuntu 18.04 LTS / 20.04 LTS / 22.04 LTS / 24.04 LTS / 25.04 : Ruby vulnerabilities (USN-7734-1) | C7: =IFERROR(__xludf.DUMMYFUNCTION("""COMPUTED_VALUE"""),9.8) -> 9.8 | D7: =IFERROR(__xludf.DUMMYFUNCTION("""COMPUTED_VALUE"""),"10.20.30.12") -> 10.20.30.12
A8: =IFERROR(__xludf.DUMMYFUNCTION("""COMPUTED_VALUE"""),"216780") -> 216780 | B8: =IFERROR(__xludf.DUMMYFUNCTION("""COMPUTED_VALUE"""),"Ubuntu 14.04 LTS / 16.04 LTS / 18.04 LTS / 20.04 LTS / 22.04 LTS / 24.04 LTS / 24.10 : libxml2 vulnerabilities (USN-7302-1)") -> Ubuntu 14.04 LTS / 16.04 LTS / 18.04 LTS / 20.04 LTS / 22.04 LTS / 24.04 LTS / 24.10 : libxml2 vulnerabilities (USN-7302-1) | C8: =IFERROR(__xludf.DUMMYFUNCTION("""COMPUTED_VALUE"""),9.8) -> 9.8 | D8: =IFERROR(__xludf.DUMMYFUNCTION("""COMPUTED_VALUE"""),"10.20.30.12") -> 10.20.30.12
A9: =IFERROR(__xludf.DUMMYFUNCTION("""COMPUTED_VALUE"""),"205548") -> 205548 | B9: =IFERROR(__xludf.DUMMYFUNCTION("""COMPUTED_VALUE"""),"Ubuntu 20.04 LTS / 22.04 LTS / 24.04 LTS : BusyBox vulnerabilities (USN-6961-1)") -> Ubuntu 20.04 LTS / 22.04 LTS / 24.04 LTS : BusyBox vulnerabilities (USN-6961-1) | C9: =IFERROR(__xludf.DUMMYFUNCTION("""COMPUTED_VALUE"""),9.8) -> 9.8 | D9: =IFERROR(__xludf.DUMMYFUNCTION("""COMPUTED_VALUE"""),"10.20.30.12") -> 10.20.30.12
A10: =IFERROR(__xludf.DUMMYFUNCTION("""COMPUTED_VALUE"""),"209121") -> 209121 | B10: =IFERROR(__xludf.DUMMYFUNCTION("""COMPUTED_VALUE"""),"Ubuntu 14.04 LTS / 16.04 LTS / 18.04 LTS / 20.04 LTS / 22.04 LTS / 24.04 LTS : libarchive vulnerabilities (USN-7070-1)") -> Ubuntu 14.04 LTS / 16.04 LTS / 18.04 LTS / 20.04 LTS / 22.04 LTS / 24.04 LTS : libarchive vulnerabilities (USN-7070-1) | C10: =IFERROR(__xludf.DUMMYFUNCTION("""COMPUTED_VALUE"""),9.8) -> 9.8 | D10: =IFERROR(__xludf.DUMMYFUNCTION("""COMPUTED_VALUE"""),"10.20.30.12") -> 10.20.30.12
A11: =IFERROR(__xludf.DUMMYFUNCTION("""COMPUTED_VALUE"""),"211522") -> 211522 | B11: =IFERROR(__xludf.DUMMYFUNCTION("""COMPUTED_VALUE"""),"Ubuntu 16.04 LTS / 18.04 LTS / 20.04 LTS / 22.04 LTS / 24.04 LTS : GLib vulnerability (USN-7114-1)") -> Ubuntu 16.04 LTS / 18.04 LTS / 20.04 LTS / 22.04 LTS / 24.04 LTS : GLib vulnerability (USN-7114-1) | C11: =IFERROR(__xludf.DUMMYFUNCTION("""COMPUTED_VALUE"""),9.8) -> 9.8 | D11: =IFERROR(__xludf.DUMMYFUNCTION("""COMPUTED_VALUE"""),"10.20.30.12") -> 10.20.30.12
A12: =IFERROR(__xludf.DUMMYFUNCTION("""COMPUTED_VALUE"""),"234343") -> 234343 | B12: =IFERROR(__xludf.DUMMYFUNCTION("""COMPUTED_VALUE"""),"Ubuntu 22.04 LTS / 24.04 LTS / 24.10 : Perl vulnerability (USN-7434-1)") -> Ubuntu 22.04 LTS / 24.04 LTS / 24.10 : Perl vulnerability (USN-7434-1) | C12: =IFERROR(__xludf.DUMMYFUNCTION("""COMPUTED_VALUE"""),9.8) -> 9.8 | D12: =IFERROR(__xludf.DUMMYFUNCTION("""COMPUTED_VALUE"""),"10.20.30.12") -> 10.20.30.12
A13: =IFERROR(__xludf.DUMMYFUNCTION("""COMPUTED_VALUE"""),"265698") -> 265698 | B13: =IFERROR(__xludf.DUMMYFUNCTION("""COMPUTED_VALUE"""),"Ubuntu 18.04 LTS / 20.04 LTS / 22.04 LTS / 24.04 LTS / 25.04 : OpenJPEG vulnerabilities (USN-7757-1)") -> Ubuntu 18.04 LTS / 20.04 LTS / 22.04 LTS / 24.04 LTS / 25.04 : OpenJPEG vulnerabilities (USN-7757-1) | C13: =IFERROR(__xludf.DUMMYFUNCTION("""COMPUTED_VALUE"""),9.8) -> 9.8 | D13: =IFERROR(__xludf.DUMMYFUNCTION("""COMPUTED_VALUE"""),"10.20.30.12") -> 10.20.30.12
A14: =IFERROR(__xludf.DUMMYFUNCTION("""COMPUTED_VALUE"""),"241063") -> 241063 | B14: =IFERROR(__xludf.DUMMYFUNCTION("""COMPUTED_VALUE"""),"Ubuntu 22.04 LTS / 24.04 LTS / 24.10 / 25.04 : libarchive vulnerabilities (USN-7601-1)") -> Ubuntu 22.04 LTS / 24.04 LTS / 24.10 / 25.04 : libarchive vulnerabilities (USN-7601-1) | C14: =IFERROR(__xludf.DUMMYFUNCTION("""COMPUTED_VALUE"""),9.8) -> 9.8 | D14: =IFERROR(__xludf.DUMMYFUNCTION("""COMPUTED_VALUE"""),"10.20.30.12") -> 10.20.30.12
A15: =IFERROR(__xludf.DUMMYFUNCTION("""COMPUTED_VALUE"""),"233470") -> 233470 | B15: =IFERROR(__xludf.DUMMYFUNCTION("""COMPUTED_VALUE"""),"Ubuntu 20.04 LTS / 22.04 LTS / 24.04 LTS / 24.10 : Ghostscript vulnerabilities (USN-7378-1)") -> Ubuntu 20.04 LTS / 22.04 LTS / 24.04 LTS / 24.10 : Ghostscript vulnerabilities (USN-7378-1) | C15: =IFERROR(__xludf.DUMMYFUNCTION("""COMPUTED_VALUE"""),9.8) -> 9.8 | D15: =IFERROR(__xludf.DUMMYFUNCTION("""COMPUTED_VALUE"""),"10.20.30.12") -> 10.20.30.12
A16: =IFERROR(__xludf.DUMMYFUNCTION("""COMPUTED_VALUE"""),"233831") -> 233831 | B16: =IFERROR(__xludf.DUMMYFUNCTION("""COMPUTED_VALUE"""),"Ubuntu 24.04 LTS / 24.10 : XZ Utils vulnerability (USN-7414-1)") -> Ubuntu 24.04 LTS / 24.10 : XZ Utils vulnerability (USN-7414-1) | C16: =IFERROR(__xludf.DUMMYFUNCTION("""COMPUTED_VALUE"""),9.8) -> 9.8 | D16: =IFERROR(__xludf.DUMMYFUNCTION("""COMPUTED_VALUE"""),"10.20.30.12") -> 10.20.30.12
A17: =IFERROR(__xludf.DUMMYFUNCTION("""COMPUTED_VALUE"""),"265092") -> 265092 | B17: =IFERROR(__xludf.DUMMYFUNCTION("""COMPUTED_VALUE"""),"Ubuntu 24.04 LTS / 25.04 : SQLite vulnerability (USN-7751-1)") -> Ubuntu 24.04 LTS / 25.04 : SQLite vulnerability (USN-7751-1) | C17: =IFERROR(__xludf.DUMMYFUNCTION("""COMPUTED_VALUE"""),9.8) -> 9.8 | D17: =IFERROR(__xludf.DUMMYFUNCTION("""COMPUTED_VALUE"""),"10.20.30.12") -> 10.20.30.12
A18: =IFERROR(__xludf.DUMMYFUNCTION("""COMPUTED_VALUE"""),"213189") -> 213189 | B18: =IFERROR(__xludf.DUMMYFUNCTION("""COMPUTED_VALUE"""),"Ubuntu 20.04 LTS / 22.04 LTS / 24.04 LTS / 24.10 : GStreamer vulnerability (USN-7174-1)") -> Ubuntu 20.04 LTS / 22.04 LTS / 24.04 LTS / 24.10 : GStreamer vulnerability (USN-7174-1) | C18: =IFERROR(__xludf.DUMMYFUNCTION("""COMPUTED_VALUE"""),9.6) -> 9.6 | D18: =IFERROR(__xludf.DUMMYFUNCTION("""COMPUTED_VALUE"""),"10.20.30.12") -> 10.20.30.12
A19: =IFERROR(__xludf.DUMMYFUNCTION("""COMPUTED_VALUE"""),"207059") -> 207059 | B19: =IFERROR(__xludf.DUMMYFUNCTION("""COMPUTED_VALUE"""),"Ubuntu 14.04 LTS / 16.04 LTS / 18.04 LTS / 20.04 LTS / 24.04 LTS : Expat vulnerabilities (USN-7000-1)") -> Ubuntu 14.04 LTS / 16.04 LTS / 18.04 LTS / 20.04 LTS / 24.04 LTS : Expat vulnerabilities (USN-7000-1) | C19: =IFERROR(__xludf.DUMMYFUNCTION("""COMPUTED_VALUE"""),9.6) -> 9.6 | D19: =IFERROR(__xludf.DUMMYFUNCTION("""COMPUTED_VALUE"""),"10.20.30.12") -> 10.20.30.12
A20: =IFERROR(__xludf.DUMMYFUNCTION("""COMPUTED_VALUE"""),"243033") -> 243033 | B20: =IFERROR(__xludf.DUMMYFUNCTION("""COMPUTED_VALUE"""),"Ubuntu 22.04 LTS / 24.04 LTS / 25.04 : SQLite vulnerability (USN-7676-1)") -> Ubuntu 22.04 LTS / 24.04 LTS / 25.04 : SQLite vulnerability (USN-7676-1) | C20: =IFERROR(__xludf.DUMMYFUNCTION("""COMPUTED_VALUE"""),9.6) -> 9.6 | D20: =IFERROR(__xludf.DUMMYFUNCTION("""COMPUTED_VALUE"""),"10.20.30.12") -> 10.20.30.12
A21: =IFERROR(__xludf.DUMMYFUNCTION("""COMPUTED_VALUE"""),"282466") -> 282466 | B21: =IFERROR(__xludf.DUMMYFUNCTION("""COMPUTED_VALUE"""),"Ubuntu 14.04 LTS / 16.04 LTS / 18.04 LTS / 20.04 LTS / 22.04 LTS / 24.04 LTS / 25.04 / 25.10 : Net-SNMP vulnerability (USN-7944-1)") -> Ubuntu 14.04 LTS / 16.04 LTS / 18.04 LTS / 20.04 LTS / 22.04 LTS / 24.04 LTS / 25.04 / 25.10 : Net-SNMP vulnerability (USN-7944-1) | C21: =IFERROR(__xludf.DUMMYFUNCTION("""COMPUTED_VALUE"""),9.6) -> 9.6 | D21: =IFERROR(__xludf.DUMMYFUNCTION("""COMPUTED_VALUE"""),"10.20.30.12") -> 10.20.30.12
A22: =IFERROR(__xludf.DUMMYFUNCTION("""COMPUTED_VALUE"""),"200162") -> 200162 | B22: =IFERROR(__xludf.DUMMYFUNCTION("""COMPUTED_VALUE"""),"PHP 8.2x < 8.2.20 Multiple Vulnerabilities") -> PHP 8.2x < 8.2.20 Multiple Vulnerabilities | C22: =IFERROR(__xludf.DUMMYFUNCTION("""COMPUTED_VALUE"""),9.433333333333334) -> 9.4333333 | D22: =IFERROR(__xludf.DUMMYFUNCTION("""COMPUTED_VALUE"""),"10.20.30.10 (megaquagga.local)") -> 10.20.30.10 (megaquagga.local)
A23: =IFERROR(__xludf.DUMMYFUNCTION("""COMPUTED_VALUE"""),"179906") -> 179906 | B23: =IFERROR(__xludf.DUMMYFUNCTION("""COMPUTED_VALUE"""),"PHP 8.2x < 8.2.9 Multiple Vulnerabilities") -> PHP 8.2x < 8.2.9 Multiple Vulnerabilities | C23: =IFERROR(__xludf.DUMMYFUNCTION("""COMPUTED_VALUE"""),9.433333333333334) -> 9.4333333 | D23: =IFERROR(__xludf.DUMMYFUNCTION("""COMPUTED_VALUE"""),"10.20.30.10 (megaquagga.local)") -> 10.20.30.10 (megaquagga.local)
A24: =IFERROR(__xludf.DUMMYFUNCTION("""COMPUTED_VALUE"""),"211671") -> 211671 | B24: =IFERROR(__xludf.DUMMYFUNCTION("""COMPUTED_VALUE"""),"PHP 8.2x < 8.2.26 Multiple Vulnerabilities") -> PHP 8.2x < 8.2.26 Multiple Vulnerabilities | C24: =IFERROR(__xludf.DUMMYFUNCTION("""COMPUTED_VALUE"""),9.433333333333334) -> 9.4333333 | D24: =IFERROR(__xludf.DUMMYFUNCTION("""COMPUTED_VALUE"""),"10.20.30.10 (megaquagga.local)") -> 10.20.30.10 (megaquagga.local)
A25: =IFERROR(__xludf.DUMMYFUNCTION("""COMPUTED_VALUE"""),"240210") -> 240210 | B25: =IFERROR(__xludf.DUMMYFUNCTION("""COMPUTED_VALUE"""),"Ubuntu 24.04 LTS / 24.10 / 25.04 : Python vulnerabilities (USN-7583-1)") -> Ubuntu 24.04 LTS / 24.10 / 25.04 : Python vulnerabilities (USN-7583-1) | C25: =IFERROR(__xludf.DUMMYFUNCTION("""COMPUTED_VALUE"""),9.4) -> 9.4 | D25: =IFERROR(__xludf.DUMMYFUNCTION("""COMPUTED_VALUE"""),"10.20.30.12") -> 10.20.30.12
A26: =IFERROR(__xludf.DUMMYFUNCTION("""COMPUTED_VALUE"""),"204924") -> 204924 | B26: =IFERROR(__xludf.DUMMYFUNCTION("""COMPUTED_VALUE"""),"Ubuntu 20.04 LTS / 22.04 LTS / 24.04 LTS : OpenSSL vulnerabilities (USN-6937-1)") -> Ubuntu 20.04 LTS / 22.04 LTS / 24.04 LTS : OpenSSL vulnerabilities (USN-6937-1) | C26: =IFERROR(__xludf.DUMMYFUNCTION("""COMPUTED_VALUE"""),9.1) -> 9.1 | D26: =IFERROR(__xludf.DUMMYFUNCTION("""COMPUTED_VALUE"""),"10.20.30.12") -> 10.20.30.12
A27: =IFERROR(__xludf.DUMMYFUNCTION("""COMPUTED_VALUE"""),"205195") -> 205195 | B27: =IFERROR(__xludf.DUMMYFUNCTION("""COMPUTED_VALUE"""),"Ubuntu 14.04 LTS / 16.04 LTS / 18.04 LTS / 20.04 LTS / 22.04 LTS / 24.04 LTS : Kerberos vulnerabilities (USN-6947-1)") -> Ubuntu 14.04 LTS / 16.04 LTS / 18.04 LTS / 20.04 LTS / 22.04 LTS / 24.04 LTS : Kerberos vulnerabilities (USN-6947-1) | C27: =IFERROR(__xludf.DUMMYFUNCTION("""COMPUTED_VALUE"""),9.1) -> 9.1 | D27: =IFERROR(__xludf.DUMMYFUNCTION("""COMPUTED_VALUE"""),"10.20.30.12") -> 10.20.30.12
A28: =IFERROR(__xludf.DUMMYFUNCTION("""COMPUTED_VALUE"""),"214997") -> 214997 | B28: =IFERROR(__xludf.DUMMYFUNCTION("""COMPUTED_VALUE"""),"Ubuntu 14.04 LTS / 16.04 LTS / 18.04 LTS / 20.04 LTS / 22.04 LTS / 24.04 LTS / 24.10 : Kerberos vulnerability (USN-7257-1)") -> Ubuntu 14.04 LTS / 16.04 LTS / 18.04 LTS / 20.04 LTS / 22.04 LTS / 24.04 LTS / 24.10 : Kerberos vulnerability (USN-7257-1) | C28: =IFERROR(__xludf.DUMMYFUNCTION("""COMPUTED_VALUE"""),9.0) -> 9 | D28: =IFERROR(__xludf.DUMMYFUNCTION("""COMPUTED_VALUE"""),"10.20.30.12") -> 10.20.30.12
A29: =IFERROR(__xludf.DUMMYFUNCTION("""COMPUTED_VALUE"""),"207822") -> 207822 | B29: =IFERROR(__xludf.DUMMYFUNCTION("""COMPUTED_VALUE"""),"PHP 8.2.x < 8.2.24 Multiple Vulnerabilities") -> PHP 8.2.x < 8.2.24 Multiple Vulnerabilities | C29: =IFERROR(__xludf.DUMMYFUNCTION("""COMPUTED_VALUE"""),8.8) -> 8.8 | D29: =IFERROR(__xludf.DUMMYFUNCTION("""COMPUTED_VALUE"""),"10.20.30.10 (megaquagga.local)") -> 10.20.30.10 (megaquagga.local)
A30: =IFERROR(__xludf.DUMMYFUNCTION("""COMPUTED_VALUE"""),"241066") -> 241066 | B30: =IFERROR(__xludf.DUMMYFUNCTION("""COMPUTED_VALUE"""),"Ubuntu 22.04 LTS / 24.04 LTS / 24.10 / 25.04 : Sudo vulnerabilities (USN-7604-1)") -> Ubuntu 22.04 LTS / 24.04 LTS / 24.10 / 25.04 : Sudo vulnerabilities (USN-7604-1) | C30: =IFERROR(__xludf.DUMMYFUNCTION("""COMPUTED_VALUE"""),8.8) -> 8.8 | D30: =IFERROR(__xludf.DUMMYFUNCTION("""COMPUTED_VALUE"""),"10.20.30.12") -> 10.20.30.12
A31: =IFERROR(__xludf.DUMMYFUNCTION("""COMPUTED_VALUE"""),"214801") -> 214801 | B31: =IFERROR(__xludf.DUMMYFUNCTION("""COMPUTED_VALUE"""),"Ubuntu 18.04 LTS / 20.04 LTS / 22.04 LTS / 24.04 LTS / 24.10 : Jinja2 vulnerabilities (USN-7244-1)") -> Ubuntu 18.04 LTS / 20.04 LTS / 22.04 LTS / 24.04 LTS / 24.10 : Jinja2 vulnerabilities (USN-7244-1) | C31: =IFERROR(__xludf.DUMMYFUNCTION("""COMPUTED_VALUE"""),8.8) -> 8.8 | D31: =IFERROR(__xludf.DUMMYFUNCTION("""COMPUTED_VALUE"""),"10.20.30.12") -> 10.20.30.12
A32: =IFERROR(__xludf.DUMMYFUNCTION("""COMPUTED_VALUE"""),"211997") -> 211997 | B32: =IFERROR(__xludf.DUMMYFUNCTION("""COMPUTED_VALUE"""),"Ubuntu 20.04 LTS / 22.04 LTS / 24.04 LTS / 24.10 : PostgreSQL vulnerabilities (USN-7132-1)") -> Ubuntu 20.04 LTS / 22.04 LTS / 24.04 LTS / 24.10 : PostgreSQL vulnerabilities (USN-7132-1) | C32: =IFERROR(__xludf.DUMMYFUNCTION("""COMPUTED_VALUE"""),8.8) -> 8.8 | D32: =IFERROR(__xludf.DUMMYFUNCTION("""COMPUTED_VALUE"""),"10.20.30.12") -> 10.20.30.12
A33: =IFERROR(__xludf.DUMMYFUNCTION("""COMPUTED_VALUE"""),"207058") -> 207058 | B33: =IFERROR(__xludf.DUMMYFUNCTION("""COMPUTED_VALUE"""),"Ubuntu 14.04 LTS / 16.04 LTS / 18.04 LTS / 20.04 LTS / 22.04 LTS / 24.04 LTS : Setuptools vulnerability (USN-7002-1)") -> Ubuntu 14.04 LTS / 16.04 LTS / 18.04 LTS / 20.04 LTS / 22.04 LTS / 24.04 LTS : Setuptools vulnerability (USN-7002-1) | C33: =IFERROR(__xludf.DUMMYFUNCTION("""COMPUTED_VALUE"""),8.8) -> 8.8 | D33: =IFERROR(__xludf.DUMMYFUNCTION("""COMPUTED_VALUE"""),"10.20.30.12") -> 10.20.30.12
A34: =IFERROR(__xludf.DUMMYFUNCTION("""COMPUTED_VALUE"""),"266308") -> 266308 | B34: =IFERROR(__xludf.DUMMYFUNCTION("""COMPUTED_VALUE"""),"Ubuntu 14.04 LTS / 16.04 LTS / 18.04 LTS / 20.04 LTS / 22.04 LTS / 24.04 LTS / 25.04 : LibTIFF vulnerabilities (USN-7783-1)") -> Ubuntu 14.04 LTS / 16.04 LTS / 18.04 LTS / 20.04 LTS / 22.04 LTS / 24.04 LTS / 25.04 : LibTIFF vulnerabilities (USN-7783-1) | C34: =IFERROR(__xludf.DUMMYFUNCTION("""COMPUTED_VALUE"""),8.8) -> 8.8 | D34: =IFERROR(__xludf.DUMMYFUNCTION("""COMPUTED_VALUE"""),"10.20.30.12") -> 10.20.30.12
A35: =IFERROR(__xludf.DUMMYFUNCTION("""COMPUTED_VALUE"""),"212270") -> 212270 | B35: =IFERROR(__xludf.DUMMYFUNCTION("""COMPUTED_VALUE"""),"Ubuntu 16.04 LTS / 18.04 LTS / 20.04 LTS / 22.04 LTS / 24.04 LTS / 24.10 : Intel Microcode vulnerabilities (USN-7149-1)") -> Ubuntu 16.04 LTS / 18.04 LTS / 20.04 LTS / 22.04 LTS / 24.04 LTS / 24.10 : Intel Microcode vulnerabilities (USN-7149-1) | C35: =IFERROR(__xludf.DUMMYFUNCTION("""COMPUTED_VALUE"""),8.8) -> 8.8 | D35: =IFERROR(__xludf.DUMMYFUNCTION("""COMPUTED_VALUE"""),"10.20.30.12") -> 10.20.30.12
A36: =IFERROR(__xludf.DUMMYFUNCTION("""COMPUTED_VALUE"""),"243039") -> 243039 | B36: =IFERROR(__xludf.DUMMYFUNCTION("""COMPUTED_VALUE"""),"Ubuntu 16.04 LTS / 18.04 LTS / 20.04 LTS / 22.04 LTS / 24.04 LTS / 25.04 : cloud-init vulnerabilities (USN-7677-1)") -> Ubuntu 16.04 LTS / 18.04 LTS / 20.04 LTS / 22.04 LTS / 24.04 LTS / 25.04 : cloud-init vulnerabilities (USN-7677-1) | C36: =IFERROR(__xludf.DUMMYFUNCTION("""COMPUTED_VALUE"""),8.8) -> 8.8 | D36: =IFERROR(__xludf.DUMMYFUNCTION("""COMPUTED_VALUE"""),"10.20.30.12") -> 10.20.30.12
A37: =IFERROR(__xludf.DUMMYFUNCTION("""COMPUTED_VALUE"""),"232707") -> 232707 | B37: =IFERROR(__xludf.DUMMYFUNCTION("""COMPUTED_VALUE"""),"PHP 8.2.x < 8.2.28 Multiple Vulnerabilities") -> PHP 8.2.x < 8.2.28 Multiple Vulnerabilities | C37: =IFERROR(__xludf.DUMMYFUNCTION("""COMPUTED_VALUE"""),8.6) -> 8.6 | D37: =IFERROR(__xludf.DUMMYFUNCTION("""COMPUTED_VALUE"""),"10.20.30.10 (megaquagga.local)") -> 10.20.30.10 (megaquagga.local)
A38: =IFERROR(__xludf.DUMMYFUNCTION("""COMPUTED_VALUE"""),"241622") -> 241622 | B38: =IFERROR(__xludf.DUMMYFUNCTION("""COMPUTED_VALUE"""),"Ubuntu 16.04 LTS / 18.04 LTS / 20.04 LTS / 22.04 LTS / 24.04 LTS / 24.10 / 25.04 : Git vulnerabilities (USN-7626-1)") -> Ubuntu 16.04 LTS / 18.04 LTS / 20.04 LTS / 22.04 LTS / 24.04 LTS / 24.10 / 25.04 : Git vulnerabilities (USN-7626-1) | C38: =IFERROR(__xludf.DUMMYFUNCTION("""COMPUTED_VALUE"""),8.6) -> 8.6 | D38: =IFERROR(__xludf.DUMMYFUNCTION("""COMPUTED_VALUE"""),"10.20.30.12") -> 10.20.30.12
A39: =IFERROR(__xludf.DUMMYFUNCTION("""COMPUTED_VALUE"""),"241291") -> 241291 | B39: =IFERROR(__xludf.DUMMYFUNCTION("""COMPUTED_VALUE"""),"PHP 8.2.x < 8.2.29 Multiple Vulnerabilities") -> PHP 8.2.x < 8.2.29 Multiple Vulnerabilities | C39: =IFERROR(__xludf.DUMMYFUNCTION("""COMPUTED_VALUE"""),7.5) -> 7.5 | D39: =IFERROR(__xludf.DUMMYFUNCTION("""COMPUTED_VALUE"""),"10.20.30.10 (megaquagga.local)") -> 10.20.30.10 (megaquagga.local)
A40: =IFERROR(__xludf.DUMMYFUNCTION("""COMPUTED_VALUE"""),"279274") -> 279274 | B40: =IFERROR(__xludf.DUMMYFUNCTION("""COMPUTED_VALUE"""),"PHP 8.2.x < 8.2.30 Multiple Vulnerabilities") -> PHP 8.2.x < 8.2.30 Multiple Vulnerabilities | C40: =IFERROR(__xludf.DUMMYFUNCTION("""COMPUTED_VALUE"""),7.5) -> 7.5 | D40: =IFERROR(__xludf.DUMMYFUNCTION("""COMPUTED_VALUE"""),"10.20.30.10 (megaquagga.local)") -> 10.20.30.10 (megaquagga.local)
...

Sheet Severity Distribution
A1: Severity | B1: Count
A2: Critical | B2: =COUNTIF('VULNERABILITY ASSESSMENT'!B:B, "Critical") -> 27
A3: High | B3: =COUNTIF('VULNERABILITY ASSESSMENT'!B:B, "High") -> 14
A4: Medium | B4: =COUNTIF('VULNERABILITY ASSESSMENT'!B:B, "Medium") -> 5
A5: Low | B5: =COUNTIF('VULNERABILITY ASSESSMENT'!B:B, "Low") -> 1
A6: Informational | B6: =COUNTIF('VULNERABILITY ASSESSMENT'!B:B, "Informational") -> 0

Sheet ❤️‍🩹 Remediation List
A1: 🏷️ Nessus ID | B1: 👋🏼 Name | C1: 🎖️ Priority | D1: 👑 Asset | E1: 🛡️ Solution | F1: ❤️‍🩹 Remediation Notes
A2: =IFERROR(__xludf.DUMMYFUNCTION("SORT( FILTER( {'VULNERABILITY ASSESSMENT'!D4:D1001, 'VULNERABILITY ASSESSMENT'!E4:E1001, 'VULNERABILITY ASSESSMENT'!J4:J1001, 'VULNERABILITY ASSESSMENT'!A4:A1001, 'VULNERABILITY ASSESSMENT'!G4:G1001}, LEN('VULNERABILITY ASSESSMENT'!D4:D1001) > 0 ), 3, FAL"&"SE )"),"58987") -> 58987 | B2: =IFERROR(__xludf.DUMMYFUNCTION("""COMPUTED_VALUE"""),"PHP Unsupported Version Detected") -> PHP Unsupported Version Detected | C2: =IFERROR(__xludf.DUMMYFUNCTION("""COMPUTED_VALUE"""),10.0) -> 10 | D2: =IFERROR(__xludf.DUMMYFUNCTION("""COMPUTED_VALUE"""),"10.20.30.10 (megaquagga.local)") -> 10.20.30.10 (megaquagga.local) | E2: =IFERROR(__xludf.DUMMYFUNCTION("""COMPUTED_VALUE"""),"Upgrade to a version of PHP that is currently supported.") -> Upgrade to a version of PHP that is currently supported.
A3: =IFERROR(__xludf.DUMMYFUNCTION("""COMPUTED_VALUE"""),"270678") -> 270678 | B3: =IFERROR(__xludf.DUMMYFUNCTION("""COMPUTED_VALUE"""),"Ubuntu 14.04 LTS / 16.04 LTS / 18.04 LTS / 20.04 LTS / 24.04 LTS / 25.04 / 25.10 : Redis vulnerability (USN-7824-1)") -> Ubuntu 14.04 LTS / 16.04 LTS / 18.04 LTS / 20.04 LTS / 24.04 LTS / 25.04 / 25.10 : Redis vulnerability (USN-7824-1) | C3: =IFERROR(__xludf.DUMMYFUNCTION("""COMPUTED_VALUE"""),9.833333333333334) -> 9.8333333 | D3: =IFERROR(__xludf.DUMMYFUNCTION("""COMPUTED_VALUE"""),"10.20.30.12") -> 10.20.30.12 | E3: =IFERROR(__xludf.DUMMYFUNCTION("""COMPUTED_VALUE"""),"Update the affected packages.") -> Update the affected packages.
A4: =IFERROR(__xludf.DUMMYFUNCTION("""COMPUTED_VALUE"""),"297660") -> 297660 | B4: =IFERROR(__xludf.DUMMYFUNCTION("""COMPUTED_VALUE"""),"Ubuntu 22.04 LTS / 24.04 LTS / 25.10 : Inetutils vulnerability (USN-7992-1)") -> Ubuntu 22.04 LTS / 24.04 LTS / 25.10 : Inetutils vulnerability (USN-7992-1) | C4: =IFERROR(__xludf.DUMMYFUNCTION("""COMPUTED_VALUE"""),9.8) -> 9.8 | D4: =IFERROR(__xludf.DUMMYFUNCTION("""COMPUTED_VALUE"""),"10.20.30.12") -> 10.20.30.12 | E4: =IFERROR(__xludf.DUMMYFUNCTION("""COMPUTED_VALUE"""),"Update the affected packages.") -> Update the affected packages.
A5: =IFERROR(__xludf.DUMMYFUNCTION("""COMPUTED_VALUE"""),"234681") -> 234681 | B5: =IFERROR(__xludf.DUMMYFUNCTION("""COMPUTED_VALUE"""),"Ubuntu 14.04 LTS / 16.04 LTS / 18.04 LTS / 20.04 LTS / 22.04 LTS / 24.04 LTS : Eclipse Mosquitto vulnerabilities (USN-7441-1)") -> Ubuntu 14.04 LTS / 16.04 LTS / 18.04 LTS / 20.04 LTS / 22.04 LTS / 24.04 LTS : Eclipse Mosquitto vulnerabilities (USN-7441-1) | C5: =IFERROR(__xludf.DUMMYFUNCTION("""COMPUTED_VALUE"""),9.8) -> 9.8 | D5: =IFERROR(__xludf.DUMMYFUNCTION("""COMPUTED_VALUE"""),"10.20.30.12") -> 10.20.30.12 | E5: =IFERROR(__xludf.DUMMYFUNCTION("""COMPUTED_VALUE"""),"Update the affected packages.") -> Update the affected packages.
A6: =IFERROR(__xludf.DUMMYFUNCTION("""COMPUTED_VALUE"""),"288869") -> 288869 | B6: =IFERROR(__xludf.DUMMYFUNCTION("""COMPUTED_VALUE"""),"Ubuntu 14.04 LTS / 16.04 LTS / 18.04 LTS / 20.04 LTS / 22.04 LTS / 24.04 LTS / 25.04 / 25.10 : klibc vulnerabilities (USN-7959-1)") -> Ubuntu 14.04 LTS / 16.04 LTS / 18.04 LTS / 20.04 LTS / 22.04 LTS / 24.04 LTS / 25.04 / 25.10 : klibc vulnerabilities (USN-7959-1) | C6: =IFERROR(__xludf.DUMMYFUNCTION("""COMPUTED_VALUE"""),9.8) -> 9.8 | D6: =IFERROR(__xludf.DUMMYFUNCTION("""COMPUTED_VALUE"""),"10.20.30.12") -> 10.20.30.12 | E6: =IFERROR(__xludf.DUMMYFUNCTION("""COMPUTED_VALUE"""),"Update the affected klibc-utils, libklibc and / or libklibc-dev packages.") -> Update the affected klibc-utils, libklibc and / or libklibc-dev packages.
A7: =IFERROR(__xludf.DUMMYFUNCTION("""COMPUTED_VALUE"""),"261428") -> 261428 | B7: =IFERROR(__xludf.DUMMYFUNCTION("""COMPUTED_VALUE"""),"Ubuntu 18.04 LTS / 20.04 LTS / 22.04 LTS / 24.04 LTS / 25.04 : Ruby vulnerabilities (USN-7734-1)") -> Ubuntu 18.04 LTS / 20.04 LTS / 22.04 LTS / 24.04 LTS / 25.04 : Ruby vulnerabilities (USN-7734-1) | C7: =IFERROR(__xludf.DUMMYFUNCTION("""COMPUTED_VALUE"""),9.8) -> 9.8 | D7: =IFERROR(__xludf.DUMMYFUNCTION("""COMPUTED_VALUE"""),"10.20.30.12") -> 10.20.30.12 | E7: =IFERROR(__xludf.DUMMYFUNCTION("""COMPUTED_VALUE"""),"Update the affected packages.") -> Update the affected packages.
A8: =IFERROR(__xludf.DUMMYFUNCTION("""COMPUTED_VALUE"""),"216780") -> 216780 | B8: =IFERROR(__xludf.DUMMYFUNCTION("""COMPUTED_VALUE"""),"Ubuntu 14.04 LTS / 16.04 LTS / 18.04 LTS / 20.04 LTS / 22.04 LTS / 24.04 LTS / 24.10 : libxml2 vulnerabilities (USN-7302-1)") -> Ubuntu 14.04 LTS / 16.04 LTS / 18.04 LTS / 20.04 LTS / 22.04 LTS / 24.04 LTS / 24.10 : libxml2 vulnerabilities (USN-7302-1) | C8: =IFERROR(__xludf.DUMMYFUNCTION("""COMPUTED_VALUE"""),9.8) -> 9.8 | D8: =IFERROR(__xludf.DUMMYFUNCTION("""COMPUTED_VALUE"""),"10.20.30.12") -> 10.20.30.12 | E8: =IFERROR(__xludf.DUMMYFUNCTION("""COMPUTED_VALUE"""),"Update the affected packages.") -> Update the affected packages.
A9: =IFERROR(__xludf.DUMMYFUNCTION("""COMPUTED_VALUE"""),"205548") -> 205548 | B9: =IFERROR(__xludf.DUMMYFUNCTION("""COMPUTED_VALUE"""),"Ubuntu 20.04 LTS / 22.04 LTS / 24.04 LTS : BusyBox vulnerabilities (USN-6961-1)") -> Ubuntu 20.04 LTS / 22.04 LTS / 24.04 LTS : BusyBox vulnerabilities (USN-6961-1) | C9: =IFERROR(__xludf.DUMMYFUNCTION("""COMPUTED_VALUE"""),9.8) -> 9.8 | D9: =IFERROR(__xludf.DUMMYFUNCTION("""COMPUTED_VALUE"""),"10.20.30.12") -> 10.20.30.12 | E9: =IFERROR(__xludf.DUMMYFUNCTION("""COMPUTED_VALUE"""),"Update the affected packages.") -> Update the affected packages.
A10: =IFERROR(__xludf.DUMMYFUNCTION("""COMPUTED_VALUE"""),"209121") -> 209121 | B10: =IFERROR(__xludf.DUMMYFUNCTION("""COMPUTED_VALUE"""),"Ubuntu 14.04 LTS / 16.04 LTS / 18.04 LTS / 20.04 LTS / 22.04 LTS / 24.04 LTS : libarchive vulnerabilities (USN-7070-1)") -> Ubuntu 14.04 LTS / 16.04 LTS / 18.04 LTS / 20.04 LTS / 22.04 LTS / 24.04 LTS : libarchive vulnerabilities (USN-7070-1) | C10: =IFERROR(__xludf.DUMMYFUNCTION("""COMPUTED_VALUE"""),9.8) -> 9.8 | D10: =IFERROR(__xludf.DUMMYFUNCTION("""COMPUTED_VALUE"""),"10.20.30.12") -> 10.20.30.12 | E10: =IFERROR(__xludf.DUMMYFUNCTION("""COMPUTED_VALUE"""),"Update the affected packages.") -> Update the affected packages.
A11: =IFERROR(__xludf.DUMMYFUNCTION("""COMPUTED_VALUE"""),"211522") -> 211522 | B11: =IFERROR(__xludf.DUMMYFUNCTION("""COMPUTED_VALUE"""),"Ubuntu 16.04 LTS / 18.04 LTS / 20.04 LTS / 22.04 LTS / 24.04 LTS : GLib vulnerability (USN-7114-1)") -> Ubuntu 16.04 LTS / 18.04 LTS / 20.04 LTS / 22.04 LTS / 24.04 LTS : GLib vulnerability (USN-7114-1) | C11: =IFERROR(__xludf.DUMMYFUNCTION("""COMPUTED_VALUE"""),9.8) -> 9.8 | D11: =IFERROR(__xludf.DUMMYFUNCTION("""COMPUTED_VALUE"""),"10.20.30.12") -> 10.20.30.12 | E11: =IFERROR(__xludf.DUMMYFUNCTION("""COMPUTED_VALUE"""),"Update the affected packages.") -> Update the affected packages.
A12: =IFERROR(__xludf.DUMMYFUNCTION("""COMPUTED_VALUE"""),"234343") -> 234343 | B12: =IFERROR(__xludf.DUMMYFUNCTION("""COMPUTED_VALUE"""),"Ubuntu 22.04 LTS / 24.04 LTS / 24.10 : Perl vulnerability (USN-7434-1)") -> Ubuntu 22.04 LTS / 24.04 LTS / 24.10 : Perl vulnerability (USN-7434-1) | C12: =IFERROR(__xludf.DUMMYFUNCTION("""COMPUTED_VALUE"""),9.8) -> 9.8 | D12: =IFERROR(__xludf.DUMMYFUNCTION("""COMPUTED_VALUE"""),"10.20.30.12") -> 10.20.30.12 | E12: =IFERROR(__xludf.DUMMYFUNCTION("""COMPUTED_VALUE"""),"Update the affected packages.") -> Update the affected packages.
A13: =IFERROR(__xludf.DUMMYFUNCTION("""COMPUTED_VALUE"""),"265698") -> 265698 | B13: =IFERROR(__xludf.DUMMYFUNCTION("""COMPUTED_VALUE"""),"Ubuntu 18.04 LTS / 20.04 LTS / 22.04 LTS / 24.04 LTS / 25.04 : OpenJPEG vulnerabilities (USN-7757-1)") -> Ubuntu 18.04 LTS / 20.04 LTS / 22.04 LTS / 24.04 LTS / 25.04 : OpenJPEG vulnerabilities (USN-7757-1) | C13: =IFERROR(__xludf.DUMMYFUNCTION("""COMPUTED_VALUE"""),9.8) -> 9.8 | D13: =IFERROR(__xludf.DUMMYFUNCTION("""COMPUTED_VALUE"""),"10.20.30.12") -> 10.20.30.12 | E13: =IFERROR(__xludf.DUMMYFUNCTION("""COMPUTED_VALUE"""),"Update the affected packages.") -> Update the affected packages.
A14: =IFERROR(__xludf.DUMMYFUNCTION("""COMPUTED_VALUE"""),"241063") -> 241063 | B14: =IFERROR(__xludf.DUMMYFUNCTION("""COMPUTED_VALUE"""),"Ubuntu 22.04 LTS / 24.04 LTS / 24.10 / 25.04 : libarchive vulnerabilities (USN-7601-1)") -> Ubuntu 22.04 LTS / 24.04 LTS / 24.10 / 25.04 : libarchive vulnerabilities (USN-7601-1) | C14: =IFERROR(__xludf.DUMMYFUNCTION("""COMPUTED_VALUE"""),9.8) -> 9.8 | D14: =IFERROR(__xludf.DUMMYFUNCTION("""COMPUTED_VALUE"""),"10.20.30.12") -> 10.20.30.12 | E14: =IFERROR(__xludf.DUMMYFUNCTION("""COMPUTED_VALUE"""),"Update the affected packages.") -> Update the affected packages.
A15: =IFERROR(__xludf.DUMMYFUNCTION("""COMPUTED_VALUE"""),"233470") -> 233470 | B15: =IFERROR(__xludf.DUMMYFUNCTION("""COMPUTED_VALUE"""),"Ubuntu 20.04 LTS / 22.04 LTS / 24.04 LTS / 24.10 : Ghostscript vulnerabilities (USN-7378-1)") -> Ubuntu 20.04 LTS / 22.04 LTS / 24.04 LTS / 24.10 : Ghostscript vulnerabilities (USN-7378-1) | C15: =IFERROR(__xludf.DUMMYFUNCTION("""COMPUTED_VALUE"""),9.8) -> 9.8 | D15: =IFERROR(__xludf.DUMMYFUNCTION("""COMPUTED_VALUE"""),"10.20.30.12") -> 10.20.30.12 | E15: =IFERROR(__xludf.DUMMYFUNCTION("""COMPUTED_VALUE"""),"Update the affected packages.") -> Update the affected packages.
A16: =IFERROR(__xludf.DUMMYFUNCTION("""COMPUTED_VALUE"""),"233831") -> 233831 | B16: =IFERROR(__xludf.DUMMYFUNCTION("""COMPUTED_VALUE"""),"Ubuntu 24.04 LTS / 24.10 : XZ Utils vulnerability (USN-7414-1)") -> Ubuntu 24.04 LTS / 24.10 : XZ Utils vulnerability (USN-7414-1) | C16: =IFERROR(__xludf.DUMMYFUNCTION("""COMPUTED_VALUE"""),9.8) -> 9.8 | D16: =IFERROR(__xludf.DUMMYFUNCTION("""COMPUTED_VALUE"""),"10.20.30.12") -> 10.20.30.12 | E16: =IFERROR(__xludf.DUMMYFUNCTION("""COMPUTED_VALUE"""),"Update the affected packages.") -> Update the affected packages.
A17: =IFERROR(__xludf.DUMMYFUNCTION("""COMPUTED_VALUE"""),"265092") -> 265092 | B17: =IFERROR(__xludf.DUMMYFUNCTION("""COMPUTED_VALUE"""),"Ubuntu 24.04 LTS / 25.04 : SQLite vulnerability (USN-7751-1)") -> Ubuntu 24.04 LTS / 25.04 : SQLite vulnerability (USN-7751-1) | C17: =IFERROR(__xludf.DUMMYFUNCTION("""COMPUTED_VALUE"""),9.8) -> 9.8 | D17: =IFERROR(__xludf.DUMMYFUNCTION("""COMPUTED_VALUE"""),"10.20.30.12") -> 10.20.30.12 | E17: =IFERROR(__xludf.DUMMYFUNCTION("""COMPUTED_VALUE"""),"Update the affected packages.") -> Update the affected packages.
A18: =IFERROR(__xludf.DUMMYFUNCTION("""COMPUTED_VALUE"""),"213189") -> 213189 | B18: =IFERROR(__xludf.DUMMYFUNCTION("""COMPUTED_VALUE"""),"Ubuntu 20.04 LTS / 22.04 LTS / 24.04 LTS / 24.10 : GStreamer vulnerability (USN-7174-1)") -> Ubuntu 20.04 LTS / 22.04 LTS / 24.04 LTS / 24.10 : GStreamer vulnerability (USN-7174-1) | C18: =IFERROR(__xludf.DUMMYFUNCTION("""COMPUTED_VALUE"""),9.6) -> 9.6 | D18: =IFERROR(__xludf.DUMMYFUNCTION("""COMPUTED_VALUE"""),"10.20.30.12") -> 10.20.30.12 | E18: =IFERROR(__xludf.DUMMYFUNCTION("""COMPUTED_VALUE"""),"Update the affected packages.") -> Update the affected packages.
A19: =IFERROR(__xludf.DUMMYFUNCTION("""COMPUTED_VALUE"""),"207059") -> 207059 | B19: =IFERROR(__xludf.DUMMYFUNCTION("""COMPUTED_VALUE"""),"Ubuntu 14.04 LTS / 16.04 LTS / 18.04 LTS / 20.04 LTS / 24.04 LTS : Expat vulnerabilities (USN-7000-1)") -> Ubuntu 14.04 LTS / 16.04 LTS / 18.04 LTS / 20.04 LTS / 24.04 LTS : Expat vulnerabilities (USN-7000-1) | C19: =IFERROR(__xludf.DUMMYFUNCTION("""COMPUTED_VALUE"""),9.6) -> 9.6 | D19: =IFERROR(__xludf.DUMMYFUNCTION("""COMPUTED_VALUE"""),"10.20.30.12") -> 10.20.30.12 | E19: =IFERROR(__xludf.DUMMYFUNCTION("""COMPUTED_VALUE"""),"Update the affected packages.") -> Update the affected packages.
A20: =IFERROR(__xludf.DUMMYFUNCTION("""COMPUTED_VALUE"""),"243033") -> 243033 | B20: =IFERROR(__xludf.DUMMYFUNCTION("""COMPUTED_VALUE"""),"Ubuntu 22.04 LTS / 24.04 LTS / 25.04 : SQLite vulnerability (USN-7676-1)") -> Ubuntu 22.04 LTS / 24.04 LTS / 25.04 : SQLite vulnerability (USN-7676-1) | C20: =IFERROR(__xludf.DUMMYFUNCTION("""COMPUTED_VALUE"""),9.6) -> 9.6 | D20: =IFERROR(__xludf.DUMMYFUNCTION("""COMPUTED_VALUE"""),"10.20.30.12") -> 10.20.30.12 | E20: =IFERROR(__xludf.DUMMYFUNCTION("""COMPUTED_VALUE"""),"Update the affected packages.") -> Update the affected packages.
A21: =IFERROR(__xludf.DUMMYFUNCTION("""COMPUTED_VALUE"""),"282466") -> 282466 | B21: =IFERROR(__xludf.DUMMYFUNCTION("""COMPUTED_VALUE"""),"Ubuntu 14.04 LTS / 16.04 LTS / 18.04 LTS / 20.04 LTS / 22.04 LTS / 24.04 LTS / 25.04 / 25.10 : Net-SNMP vulnerability (USN-7944-1)") -> Ubuntu 14.04 LTS / 16.04 LTS / 18.04 LTS / 20.04 LTS / 22.04 LTS / 24.04 LTS / 25.04 / 25.10 : Net-SNMP vulnerability (USN-7944-1) | C21: =IFERROR(__xludf.DUMMYFUNCTION("""COMPUTED_VALUE"""),9.6) -> 9.6 | D21: =IFERROR(__xludf.DUMMYFUNCTION("""COMPUTED_VALUE"""),"10.20.30.12") -> 10.20.30.12 | E21: =IFERROR(__xludf.DUMMYFUNCTION("""COMPUTED_VALUE"""),"Update the affected packages.") -> Update the affected packages.
A22: =IFERROR(__xludf.DUMMYFUNCTION("""COMPUTED_VALUE"""),"200162") -> 200162 | B22: =IFERROR(__xludf.DUMMYFUNCTION("""COMPUTED_VALUE"""),"PHP 8.2x < 8.2.20 Multiple Vulnerabilities") -> PHP 8.2x < 8.2.20 Multiple Vulnerabilities | C22: =IFERROR(__xludf.DUMMYFUNCTION("""COMPUTED_VALUE"""),9.433333333333334) -> 9.4333333 | D22: =IFERROR(__xludf.DUMMYFUNCTION("""COMPUTED_VALUE"""),"10.20.30.10 (megaquagga.local)") -> 10.20.30.10 (megaquagga.local) | E22: =IFERROR(__xludf.DUMMYFUNCTION("""COMPUTED_VALUE"""),"Upgrade to PHP version 8.2.20 or later.") -> Upgrade to PHP version 8.2.20 or later.
A23: =IFERROR(__xludf.DUMMYFUNCTION("""COMPUTED_VALUE"""),"179906") -> 179906 | B23: =IFERROR(__xludf.DUMMYFUNCTION("""COMPUTED_VALUE"""),"PHP 8.2x < 8.2.9 Multiple Vulnerabilities") -> PHP 8.2x < 8.2.9 Multiple Vulnerabilities | C23: =IFERROR(__xludf.DUMMYFUNCTION("""COMPUTED_VALUE"""),9.433333333333334) -> 9.4333333 | D23: =IFERROR(__xludf.DUMMYFUNCTION("""COMPUTED_VALUE"""),"10.20.30.10 (megaquagga.local)") -> 10.20.30.10 (megaquagga.local) | E23: =IFERROR(__xludf.DUMMYFUNCTION("""COMPUTED_VALUE"""),"Upgrade to PHP version 8.2.9 or later.") -> Upgrade to PHP version 8.2.9 or later.
A24: =IFERROR(__xludf.DUMMYFUNCTION("""COMPUTED_VALUE"""),"211671") -> 211671 | B24: =IFERROR(__xludf.DUMMYFUNCTION("""COMPUTED_VALUE"""),"PHP 8.2x < 8.2.26 Multiple Vulnerabilities") -> PHP 8.2x < 8.2.26 Multiple Vulnerabilities | C24: =IFERROR(__xludf.DUMMYFUNCTION("""COMPUTED_VALUE"""),9.433333333333334) -> 9.4333333 | D24: =IFERROR(__xludf.DUMMYFUNCTION("""COMPUTED_VALUE"""),"10.20.30.10 (megaquagga.local)") -> 10.20.30.10 (megaquagga.local) | E24: =IFERROR(__xludf.DUMMYFUNCTION("""COMPUTED_VALUE"""),"Upgrade to PHP version 8.2.26 or later.") -> Upgrade to PHP version 8.2.26 or later.
A25: =IFERROR(__xludf.DUMMYFUNCTION("""COMPUTED_VALUE"""),"240210") -> 240210 | B25: =IFERROR(__xludf.DUMMYFUNCTION("""COMPUTED_VALUE"""),"Ubuntu 24.04 LTS / 24.10 / 25.04 : Python vulnerabilities (USN-7583-1)") -> Ubuntu 24.04 LTS / 24.10 / 25.04 : Python vulnerabilities (USN-7583-1) | C25: =IFERROR(__xludf.DUMMYFUNCTION("""COMPUTED_VALUE"""),9.4) -> 9.4 | D25: =IFERROR(__xludf.DUMMYFUNCTION("""COMPUTED_VALUE"""),"10.20.30.12") -> 10.20.30.12 | E25: =IFERROR(__xludf.DUMMYFUNCTION("""COMPUTED_VALUE"""),"Update the affected packages.") -> Update the affected packages.
A26: =IFERROR(__xludf.DUMMYFUNCTION("""COMPUTED_VALUE"""),"204924") -> 204924 | B26: =IFERROR(__xludf.DUMMYFUNCTION("""COMPUTED_VALUE"""),"Ubuntu 20.04 LTS / 22.04 LTS / 24.04 LTS : OpenSSL vulnerabilities (USN-6937-1)") -> Ubuntu 20.04 LTS / 22.04 LTS / 24.04 LTS : OpenSSL vulnerabilities (USN-6937-1) | C26: =IFERROR(__xludf.DUMMYFUNCTION("""COMPUTED_VALUE"""),9.1) -> 9.1 | D26: =IFERROR(__xludf.DUMMYFUNCTION("""COMPUTED_VALUE"""),"10.20.30.12") -> 10.20.30.12 | E26: =IFERROR(__xludf.DUMMYFUNCTION("""COMPUTED_VALUE"""),"Update the affected packages.") -> Update the affected packages.
A27: =IFERROR(__xludf.DUMMYFUNCTION("""COMPUTED_VALUE"""),"205195") -> 205195 | B27: =IFERROR(__xludf.DUMMYFUNCTION("""COMPUTED_VALUE"""),"Ubuntu 14.04 LTS / 16.04 LTS / 18.04 LTS / 20.04 LTS / 22.04 LTS / 24.04 LTS : Kerberos vulnerabilities (USN-6947-1)") -> Ubuntu 14.04 LTS / 16.04 LTS / 18.04 LTS / 20.04 LTS / 22.04 LTS / 24.04 LTS : Kerberos vulnerabilities (USN-6947-1) | C27: =IFERROR(__xludf.DUMMYFUNCTION("""COMPUTED_VALUE"""),9.1) -> 9.1 | D27: =IFERROR(__xludf.DUMMYFUNCTION("""COMPUTED_VALUE"""),"10.20.30.12") -> 10.20.30.12 | E27: =IFERROR(__xludf.DUMMYFUNCTION("""COMPUTED_VALUE"""),"Update the affected packages.") -> Update the affected packages.
A28: =IFERROR(__xludf.DUMMYFUNCTION("""COMPUTED_VALUE"""),"214997") -> 214997 | B28: =IFERROR(__xludf.DUMMYFUNCTION("""COMPUTED_VALUE"""),"Ubuntu 14.04 LTS / 16.04 LTS / 18.04 LTS / 20.04 LTS / 22.04 LTS / 24.04 LTS / 24.10 : Kerberos vulnerability (USN-7257-1)") -> Ubuntu 14.04 LTS / 16.04 LTS / 18.04 LTS / 20.04 LTS / 22.04 LTS / 24.04 LTS / 24.10 : Kerberos vulnerability (USN-7257-1) | C28: =IFERROR(__xludf.DUMMYFUNCTION("""COMPUTED_VALUE"""),9.0) -> 9 | D28: =IFERROR(__xludf.DUMMYFUNCTION("""COMPUTED_VALUE"""),"10.20.30.12") -> 10.20.30.12 | E28: =IFERROR(__xludf.DUMMYFUNCTION("""COMPUTED_VALUE"""),"Update the affected packages.") -> Update the affected packages.
A29: =IFERROR(__xludf.DUMMYFUNCTION("""COMPUTED_VALUE"""),"207822") -> 207822 | B29: =IFERROR(__xludf.DUMMYFUNCTION("""COMPUTED_VALUE"""),"PHP 8.2.x < 8.2.24 Multiple Vulnerabilities") -> PHP 8.2.x < 8.2.24 Multiple Vulnerabilities | C29: =IFERROR(__xludf.DUMMYFUNCTION("""COMPUTED_VALUE"""),8.8) -> 8.8 | D29: =IFERROR(__xludf.DUMMYFUNCTION("""COMPUTED_VALUE"""),"10.20.30.10 (megaquagga.local)") -> 10.20.30.10 (megaquagga.local) | E29: =IFERROR(__xludf.DUMMYFUNCTION("""COMPUTED_VALUE"""),"Upgrade to PHP version 8.2.24 or later.") -> Upgrade to PHP version 8.2.24 or later.
A30: =IFERROR(__xludf.DUMMYFUNCTION("""COMPUTED_VALUE"""),"241066") -> 241066 | B30: =IFERROR(__xludf.DUMMYFUNCTION("""COMPUTED_VALUE"""),"Ubuntu 22.04 LTS / 24.04 LTS / 24.10 / 25.04 : Sudo vulnerabilities (USN-7604-1)") -> Ubuntu 22.04 LTS / 24.04 LTS / 24.10 / 25.04 : Sudo vulnerabilities (USN-7604-1) | C30: =IFERROR(__xludf.DUMMYFUNCTION("""COMPUTED_VALUE"""),8.8) -> 8.8 | D30: =IFERROR(__xludf.DUMMYFUNCTION("""COMPUTED_VALUE"""),"10.20.30.12") -> 10.20.30.12 | E30: =IFERROR(__xludf.DUMMYFUNCTION("""COMPUTED_VALUE"""),"Update the affected libnss-sudo, sudo and / or sudo-ldap packages.") -> Update the affected libnss-sudo, sudo and / or sudo-ldap packages.
A31: =IFERROR(__xludf.DUMMYFUNCTION("""COMPUTED_VALUE"""),"214801") -> 214801 | B31: =IFERROR(__xludf.DUMMYFUNCTION("""COMPUTED_VALUE"""),"Ubuntu 18.04 LTS / 20.04 LTS / 22.04 LTS / 24.04 LTS / 24.10 : Jinja2 vulnerabilities (USN-7244-1)") -> Ubuntu 18.04 LTS / 20.04 LTS / 22.04 LTS / 24.04 LTS / 24.10 : Jinja2 vulnerabilities (USN-7244-1) | C31: =IFERROR(__xludf.DUMMYFUNCTION("""COMPUTED_VALUE"""),8.8) -> 8.8 | D31: =IFERROR(__xludf.DUMMYFUNCTION("""COMPUTED_VALUE"""),"10.20.30.12") -> 10.20.30.12 | E31: =IFERROR(__xludf.DUMMYFUNCTION("""COMPUTED_VALUE"""),"Update the affected python-jinja2 and / or python3-jinja2 packages.") -> Update the affected python-jinja2 and / or python3-jinja2 packages.
A32: =IFERROR(__xludf.DUMMYFUNCTION("""COMPUTED_VALUE"""),"211997") -> 211997 | B32: =IFERROR(__xludf.DUMMYFUNCTION("""COMPUTED_VALUE"""),"Ubuntu 20.04 LTS / 22.04 LTS / 24.04 LTS / 24.10 : PostgreSQL vulnerabilities (USN-7132-1)") -> Ubuntu 20.04 LTS / 22.04 LTS / 24.04 LTS / 24.10 : PostgreSQL vulnerabilities (USN-7132-1) | C32: =IFERROR(__xludf.DUMMYFUNCTION("""COMPUTED_VALUE"""),8.8) -> 8.8 | D32: =IFERROR(__xludf.DUMMYFUNCTION("""COMPUTED_VALUE"""),"10.20.30.12") -> 10.20.30.12 | E32: =IFERROR(__xludf.DUMMYFUNCTION("""COMPUTED_VALUE"""),"Update the affected packages.") -> Update the affected packages.
A33: =IFERROR(__xludf.DUMMYFUNCTION("""COMPUTED_VALUE"""),"207058") -> 207058 | B33: =IFERROR(__xludf.DUMMYFUNCTION("""COMPUTED_VALUE"""),"Ubuntu 14.04 LTS / 16.04 LTS / 18.04 LTS / 20.04 LTS / 22.04 LTS / 24.04 LTS : Setuptools vulnerability (USN-7002-1)") -> Ubuntu 14.04 LTS / 16.04 LTS / 18.04 LTS / 20.04 LTS / 22.04 LTS / 24.04 LTS : Setuptools vulnerability (USN-7002-1) | C33: =IFERROR(__xludf.DUMMYFUNCTION("""COMPUTED_VALUE"""),8.8) -> 8.8 | D33: =IFERROR(__xludf.DUMMYFUNCTION("""COMPUTED_VALUE"""),"10.20.30.12") -> 10.20.30.12 | E33: =IFERROR(__xludf.DUMMYFUNCTION("""COMPUTED_VALUE"""),"Update the affected packages.") -> Update the affected packages.
A34: =IFERROR(__xludf.DUMMYFUNCTION("""COMPUTED_VALUE"""),"266308") -> 266308 | B34: =IFERROR(__xludf.DUMMYFUNCTION("""COMPUTED_VALUE"""),"Ubuntu 14.04 LTS / 16.04 LTS / 18.04 LTS / 20.04 LTS / 22.04 LTS / 24.04 LTS / 25.04 : LibTIFF vulnerabilities (USN-7783-1)") -> Ubuntu 14.04 LTS / 16.04 LTS / 18.04 LTS / 20.04 LTS / 22.04 LTS / 24.04 LTS / 25.04 : LibTIFF vulnerabilities (USN-7783-1) | C34: =IFERROR(__xludf.DUMMYFUNCTION("""COMPUTED_VALUE"""),8.8) -> 8.8 | D34: =IFERROR(__xludf.DUMMYFUNCTION("""COMPUTED_VALUE"""),"10.20.30.12") -> 10.20.30.12 | E34: =IFERROR(__xludf.DUMMYFUNCTION("""COMPUTED_VALUE"""),"Update the affected packages.") -> Update the affected packages.
A35: =IFERROR(__xludf.DUMMYFUNCTION("""COMPUTED_VALUE"""),"212270") -> 212270 | B35: =IFERROR(__xludf.DUMMYFUNCTION("""COMPUTED_VALUE"""),"Ubuntu 16.04 LTS / 18.04 LTS / 20.04 LTS / 22.04 LTS / 24.04 LTS / 24.10 : Intel Microcode vulnerabilities (USN-7149-1)") -> Ubuntu 16.04 LTS / 18.04 LTS / 20.04 LTS / 22.04 LTS / 24.04 LTS / 24.10 : Intel Microcode vulnerabilities (USN-7149-1) | C35: =IFERROR(__xludf.DUMMYFUNCTION("""COMPUTED_VALUE"""),8.8) -> 8.8 | D35: =IFERROR(__xludf.DUMMYFUNCTION("""COMPUTED_VALUE"""),"10.20.30.12") -> 10.20.30.12 | E35: =IFERROR(__xludf.DUMMYFUNCTION("""COMPUTED_VALUE"""),"Update the affected intel-microcode package.") -> Update the affected intel-microcode package.
A36: =IFERROR(__xludf.DUMMYFUNCTION("""COMPUTED_VALUE"""),"243039") -> 243039 | B36: =IFERROR(__xludf.DUMMYFUNCTION("""COMPUTED_VALUE"""),"Ubuntu 16.04 LTS / 18.04 LTS / 20.04 LTS / 22.04 LTS / 24.04 LTS / 25.04 : cloud-init vulnerabilities (USN-7677-1)") -> Ubuntu 16.04 LTS / 18.04 LTS / 20.04 LTS / 22.04 LTS / 24.04 LTS / 25.04 : cloud-init vulnerabilities (USN-7677-1) | C36: =IFERROR(__xludf.DUMMYFUNCTION("""COMPUTED_VALUE"""),8.8) -> 8.8 | D36: =IFERROR(__xludf.DUMMYFUNCTION("""COMPUTED_VALUE"""),"10.20.30.12") -> 10.20.30.12 | E36: =IFERROR(__xludf.DUMMYFUNCTION("""COMPUTED_VALUE"""),"Update the affected packages.") -> Update the affected packages.
A37: =IFERROR(__xludf.DUMMYFUNCTION("""COMPUTED_VALUE"""),"232707") -> 232707 | B37: =IFERROR(__xludf.DUMMYFUNCTION("""COMPUTED_VALUE"""),"PHP 8.2.x < 8.2.28 Multiple Vulnerabilities") -> PHP 8.2.x < 8.2.28 Multiple Vulnerabilities | C37: =IFERROR(__xludf.DUMMYFUNCTION("""COMPUTED_VALUE"""),8.6) -> 8.6 | D37: =IFERROR(__xludf.DUMMYFUNCTION("""COMPUTED_VALUE"""),"10.20.30.10 (megaquagga.local)") -> 10.20.30.10 (megaquagga.local) | E37: =IFERROR(__xludf.DUMMYFUNCTION("""COMPUTED_VALUE"""),"Upgrade to PHP version 8.2.28 or later.") -> Upgrade to PHP version 8.2.28 or later.
A38: =IFERROR(__xludf.DUMMYFUNCTION("""COMPUTED_VALUE"""),"241622") -> 241622 | B38: =IFERROR(__xludf.DUMMYFUNCTION("""COMPUTED_VALUE"""),"Ubuntu 16.04 LTS / 18.04 LTS / 20.04 LTS / 22.04 LTS / 24.04 LTS / 24.10 / 25.04 : Git vulnerabilities (USN-7626-1)") -> Ubuntu 16.04 LTS / 18.04 LTS / 20.04 LTS / 22.04 LTS / 24.04 LTS / 24.10 / 25.04 : Git vulnerabilities (USN-7626-1) | C38: =IFERROR(__xludf.DUMMYFUNCTION("""COMPUTED_VALUE"""),8.6) -> 8.6 | D38: =IFERROR(__xludf.DUMMYFUNCTION("""COMPUTED_VALUE"""),"10.20.30.12") -> 10.20.30.12 | E38: =IFERROR(__xludf.DUMMYFUNCTION("""COMPUTED_VALUE"""),"Update the affected packages.") -> Update the affected packages.
A39: =IFERROR(__xludf.DUMMYFUNCTION("""COMPUTED_VALUE"""),"241291") -> 241291 | B39: =IFERROR(__xludf.DUMMYFUNCTION("""COMPUTED_VALUE"""),"PHP 8.2.x < 8.2.29 Multiple Vulnerabilities") -> PHP 8.2.x < 8.2.29 Multiple Vulnerabilities | C39: =IFERROR(__xludf.DUMMYFUNCTION("""COMPUTED_VALUE"""),7.5) -> 7.5 | D39: =IFERROR(__xludf.DUMMYFUNCTION("""COMPUTED_VALUE"""),"10.20.30.10 (megaquagga.local)") -> 10.20.30.10 (megaquagga.local) | E39: =IFERROR(__xludf.DUMMYFUNCTION("""COMPUTED_VALUE"""),"Upgrade to PHP version 8.2.29 or later.") -> Upgrade to PHP version 8.2.29 or later.
A40: =IFERROR(__xludf.DUMMYFUNCTION("""COMPUTED_VALUE"""),"279274") -> 279274 | B40: =IFERROR(__xludf.DUMMYFUNCTION("""COMPUTED_VALUE"""),"PHP 8.2.x < 8.2.30 Multiple Vulnerabilities") -> PHP 8.2.x < 8.2.30 Multiple Vulnerabilities | C40: =IFERROR(__xludf.DUMMYFUNCTION("""COMPUTED_VALUE"""),7.5) -> 7.5 | D40: =IFERROR(__xludf.DUMMYFUNCTION("""COMPUTED_VALUE"""),"10.20.30.10 (megaquagga.local)") -> 10.20.30.10 (megaquagga.local) | E40: =IFERROR(__xludf.DUMMYFUNCTION("""COMPUTED_VALUE"""),"Upgrade to PHP version 8.2.30 or later.") -> Upgrade to PHP version 8.2.30 or later.
...
